Workbook

Sheet INVOICE
B1: S A M Perera
B2: Con Address
B3: Contact Numbers:-
B5: Bill To: | C5: Sri Lanka Telecom (Services) Limited | E5: Invoice Number | G5: : | H5: {=IF(B1="","",UPPER(IF(COUNTA(_xlfn.TEXTSPLIT(B1," "))>1,LEFT(_xlfn.TEXTJOIN("",TRUE,LEFT(_xlfn.TEXTSPLIT(B1," "),1))&"SS",3),LEFT(B1&"SS",3)))&"/CENTRAL/"&UPPER(D12)&"/NC/26/"&UPPER(TEXT(H8,"MMM"))&"/1")} -> SAM/CENTRAL/KY/NC/26/DEC/1
C6: OSP Division, 148/2/A, New Kandy Road, | E6: Registered Number | G6: : | H6: SLTS/OSP/2025/2026/000
C7: Bandarawatta,Biyagama. | E7: Invoice Date | G7: : | H7: =(TODAY()) -> 46207
E8: Job Related Month | G8: : | H8: 46357
F9: Invoice | G9: : | H9: A
B11: Sn | C11: Description | D11: RTOM | E11: Qty | F11: Unit Rate | H11: Amount
B12: =IF(C12<>"",COUNTIF($C$12:C12,"<>"),"") | D12: KY | F12: =IFERROR(IF(OR(D12="CEN",D12="HK",D12="MD"),VLOOKUP(INVOICE!C12,Table1[[WORK]:[OTHER]],2,FALSE),VLOOKUP(INVOICE!C12,Table1[[WORK]:[OTHER]],4,FALSE))," ") | H12: =IFERROR(E12*F12," ")
B13: =IF(C13<>"",COUNTIF($C$12:C13,"<>"),"") | F13: =IFERROR(IF(OR(D13="CEN",D13="HK",D13="MD"),VLOOKUP(INVOICE!C13,Table1[[WORK]:[OTHER]],2,FALSE),VLOOKUP(INVOICE!C13,Table1[[WORK]:[OTHER]],4,FALSE))," ") | H13: =IFERROR(E13*F13," ")
B14: =IF(C14<>"",COUNTIF($C$12:C14,"<>"),"") | F14: =IFERROR(IF(OR(D14="CEN",D14="HK",D14="MD"),VLOOKUP(INVOICE!C14,Table1[[WORK]:[OTHER]],2,FALSE),VLOOKUP(INVOICE!C14,Table1[[WORK]:[OTHER]],4,FALSE))," ") | H14: =IFERROR(E14*F14," ")
B15: =IF(C15<>"",COUNTIF($C$12:C15,"<>"),"") | F15: =IFERROR(IF(OR(D15="CEN",D15="HK",D15="MD"),VLOOKUP(INVOICE!C15,Table1[[WORK]:[OTHER]],2,FALSE),VLOOKUP(INVOICE!C15,Table1[[WORK]:[OTHER]],4,FALSE))," ") | H15: =IFERROR(E15*F15," ")
B16: =IF(C16<>"",COUNTIF($C$12:C16,"<>"),"") | F16: =IFERROR(IF(OR(D16="CEN",D16="HK",D16="MD"),VLOOKUP(INVOICE!C16,Table1[[WORK]:[OTHER]],2,FALSE),VLOOKUP(INVOICE!C16,Table1[[WORK]:[OTHER]],4,FALSE))," ") | H16: =IFERROR(E16*F16," ")
B17: =IF(C17<>"",COUNTIF($C$12:C17,"<>"),"") | F17: =IFERROR(IF(OR(D17="CEN",D17="HK",D17="MD"),VLOOKUP(INVOICE!C17,Table1[[WORK]:[OTHER]],2,FALSE),VLOOKUP(INVOICE!C17,Table1[[WORK]:[OTHER]],4,FALSE))," ") | H17: =IFERROR(E17*F17," ")
B18: =IF(C18<>"",COUNTIF($C$12:C18,"<>"),"") | F18: =IFERROR(IF(OR(D18="CEN",D18="HK",D18="MD"),VLOOKUP(INVOICE!C18,Table1[[WORK]:[OTHER]],2,FALSE),VLOOKUP(INVOICE!C18,Table1[[WORK]:[OTHER]],4,FALSE))," ") | H18: =IFERROR(E18*F18," ")
B19: =IF(C19<>"",COUNTIF($C$12:C19,"<>"),"") | F19: =IFERROR(IF(OR(D19="CEN",D19="HK",D19="MD"),VLOOKUP(INVOICE!C19,Table1[[WORK]:[OTHER]],2,FALSE),VLOOKUP(INVOICE!C19,Table1[[WORK]:[OTHER]],4,FALSE))," ") | H19: =IFERROR(E19*F19," ")
B20: =IF(C20<>"",COUNTIF($C$12:C20,"<>"),"") | F20: =IFERROR(IF(OR(D20="CEN",D20="HK",D20="MD"),VLOOKUP(INVOICE!C20,Table1[[WORK]:[OTHER]],2,FALSE),VLOOKUP(INVOICE!C20,Table1[[WORK]:[OTHER]],4,FALSE))," ")
B21: =IF(C21<>"",COUNTIF($C$12:C21,"<>"),"") | F21: =IFERROR(IF(OR(D21="CEN",D21="HK",D21="MD"),VLOOKUP(INVOICE!C21,Table1[[WORK]:[OTHER]],2,FALSE),VLOOKUP(INVOICE!C21,Table1[[WORK]:[OTHER]],4,FALSE))," ")
B22: =IF(C22<>"",COUNTIF($C$12:C22,"<>"),"") | F22: =IFERROR(IF(OR(D22="CEN",D22="HK",D22="MD"),VLOOKUP(INVOICE!C22,Table1[[WORK]:[OTHER]],2,FALSE),VLOOKUP(INVOICE!C22,Table1[[WORK]:[OTHER]],4,FALSE))," ")
B23: =IF(C23<>"",COUNTIF($C$12:C23,"<>"),"") | F23: =IFERROR(IF(OR(D23="CEN",D23="HK",D23="MD"),VLOOKUP(INVOICE!C23,Table1[[WORK]:[OTHER]],2,FALSE),VLOOKUP(INVOICE!C23,Table1[[WORK]:[OTHER]],4,FALSE))," ")
B24: =IF(C24<>"",COUNTIF($C$12:C24,"<>"),"") | F24: =IFERROR(IF(OR(D24="CEN",D24="HK",D24="MD"),VLOOKUP(INVOICE!C24,Table1[[WORK]:[OTHER]],2,FALSE),VLOOKUP(INVOICE!C24,Table1[[WORK]:[OTHER]],4,FALSE))," ")
B25: =IF(C25<>"",COUNTIF($C$12:C25,"<>"),"") | F25: =IFERROR(IF(OR(D25="CEN",D25="HK",D25="MD"),VLOOKUP(INVOICE!C25,Table1[[WORK]:[OTHER]],2,FALSE),VLOOKUP(INVOICE!C25,Table1[[WORK]:[OTHER]],4,FALSE))," ")
B26: =IF(C26<>"",COUNTIF($C$12:C26,"<>"),"") | F26: =IFERROR(IF(OR(D26="CEN",D26="HK",D26="MD"),VLOOKUP(INVOICE!C26,Table1[[WORK]:[OTHER]],2,FALSE),VLOOKUP(INVOICE!C26,Table1[[WORK]:[OTHER]],4,FALSE))," ")
B27: =IF(C27<>"",COUNTIF($C$12:C27,"<>"),"") | F27: =IFERROR(IF(OR(D27="CEN",D27="HK",D27="MD"),VLOOKUP(INVOICE!C27,Table1[[WORK]:[OTHER]],2,FALSE),VLOOKUP(INVOICE!C27,Table1[[WORK]:[OTHER]],4,FALSE))," ")
B28: =IF(C28<>"",COUNTIF($C$12:C28,"<>"),"") | F28: =IFERROR(IF(OR(D28="CEN",D28="HK",D28="MD"),VLOOKUP(INVOICE!C28,Table1[[WORK]:[OTHER]],2,FALSE),VLOOKUP(INVOICE!C28,Table1[[WORK]:[OTHER]],4,FALSE))," ")
B29: =IF(C29<>"",COUNTIF($C$12:C29,"<>"),"") | F29: =IFERROR(IF(OR(D29="CEN",D29="HK",D29="MD"),VLOOKUP(INVOICE!C29,Table1[[WORK]:[OTHER]],2,FALSE),VLOOKUP(INVOICE!C29,Table1[[WORK]:[OTHER]],4,FALSE))," ") | H29: =IFERROR(E29*F29," ")
B30: =IF(C30<>"",COUNTIF($C$12:C30,"<>"),"") | F30: =IFERROR(IF(OR(D30="CEN",D30="HK",D30="MD"),VLOOKUP(INVOICE!C30,Table1[[WORK]:[OTHER]],2,FALSE),VLOOKUP(INVOICE!C30,Table1[[WORK]:[OTHER]],4,FALSE))," ") | H30: =IFERROR(E30*F30," ")
E31: Grand Total (Rs.) | H31: =SUM(H12:H30) -> 0
F32: =IF(H9="A",90%,IF(H9="B",10%,5%)) -> 0.9 | H32: =H31*F32 -> 0
B35: I do here by certify that the above details are true and correct.
C38: …................................................ | E38: ……………………………………
C39: Prepared By: | E39: Received By:
C40: "Contractor Name" | E40: Should be Sign by SLTS officer
B42: Cheque should be drawn in favour of "….................................."
B43: Account No: | C43: Contractor's Account Number
B44: Bank | C44: Name of the Bank
B45: Branch | C45: Branch and Branch code
B47: SLTS Use Only:
C48: Regional Signature | D48: Head Office Signature | H48: Finanace
...

Sheet FTTH
A1: Contractor Name: | C1: =INVOICE!B1 -> S A M Perera | O1: Invoice No : | P1: =INVOICE!H5 -> SAM/CENTRAL/KY/NC/26/DEC/1
A3: Team 1 - I-Shamp Mobile Team No - | J3: RTOM -
A4: NO | B4: Complete Date | C4: TP Number | D4: Configs | E4: RTOM | F4: F-1 | G4: G-1 | H4: DW-LH | I4: DW-CH | J4: DW-RT | K4: IW-N | L4: CAT 5 | M4: FAC | N4: F ROSSETTE | O4: TOP BOLT | P4: CONDUITS | Q4: CASING | R4: Pole details & Remarks
A5: 1
A6: 2
A7: 3
A8: 4
A9: 5
A10: 6
A11: 7
A12: 8
A13: 9
A14: 10
A15: 11
A16: 12
... A44: 40
A45: Material Totals | F45: =SUM(F19:F44) -> 0 | G45: =SUM(G19:G44) -> 0 | H45: =SUM(H19:H44) -> 0 | I45: =SUM(I19:I44) -> 0 | J45: =SUM(J19:J44) -> 0 | K45: =SUM(K19:K44) -> 0 | L45: =SUM(L19:L44) -> 0 | M45: =SUM(M19:M44) -> 0 | ... Q45: =SUM(Q19:Q44) -> 0
A48: …………………………….. | D48: ………………..…………
A49: Prepared By: | D49: Checked By:
D50: (With rubber stamp)
A52: Contractor Name: | C52: =C1 -> S A M Perera | O52: Invoice No : | P52: =P1 -> SAM/CENTRAL/KY/NC/26/DEC/1
A54: Team 2 - I-Shamp Mobile Team No - | J54: RTOM -
A55: NO | B55: Complete Date | C55: TP Number | D55: Configs | E55: RTOM | F55: F-1 | G55: G-1 | H55: DW-LH | I55: DW-CH | J55: DW-RT | K55: IW-N | L55: CAT 5 | M55: FAC | N55: F ROSSETTE | O55: TOP BOLT | P55: CONDUITS | Q55: CASING | R55: Pole details & Remarks
A56: 1
A57: 2
A58: 3
A59: 4
A60: 5
A61: 6
A62: 7
A63: 8
A64: 9
A65: 10
A66: 11
A67: 12
... A95: 40
A96: Material Totals | F96: =SUM(F70:F95) -> 0 | G96: =SUM(G70:G95) -> 0 | H96: =SUM(H70:H95) -> 0 | I96: =SUM(I70:I95) -> 0 | J96: =SUM(J70:J95) -> 0 | K96: =SUM(K70:K95) -> 0 | L96: =SUM(L70:L95) -> 0 | M96: =SUM(M70:M95) -> 0 | ... Q96: =SUM(Q70:Q95) -> 0
A99: …………………………….. | D99: ………………..…………
A100: Prepared By: | D100: Checked By:
D101: (With rubber stamp)
...

Sheet PSTN
B1: Contractor Name: | D1: =INVOICE!B1 -> S A M Perera | N1: Invoice No : | Q1: =CONCATENATE(INVOICE!H5,"-",INVOICE!H9) -> SAM/CENTRAL/KY/NC/26/DEC/1-A
B3: PSTN - (RTOM)
A4: No | B4: No | C4: TP Number | D4: RTOM | E4: Complete Date | F4: DW-DW | G4: IW-N | H4: DW-CH | I4: DW-LH | J4: DW-RT | K4: DW-DF | L4: ROSSETTE | M4: EARTH ROD | N4: EARTH WIRE | O4: TOP BOLT | P4: CONDUITS | Q4: Pole details & Remarks
A5: 1 | B5: 1
A6: 2 | B6: 2
A7: 3 | B7: 3
A8: 4 | B8: 4
A9: 5 | B9: 5
A10: 6 | B10: 6
A11: 7 | B11: 7
A12: 8 | B12: 8
A13: 9 | B13: 9
A14: 10 | B14: 10
A15: 11 | B15: 11
A16: 12 | B16: 12
... A23: 19 | B23: 19
B24: 20
A25: 0 | B25: Material Totals | F25: =SUM(F5:F24) -> 0 | G25: =SUM(G5:G24) -> 0 | H25: =SUM(H5:H24) -> 0 | I25: =SUM(I5:I24) -> 0 | J25: =SUM(J5:J24) -> 0 | K25: =SUM(K5:K24) -> 0 | L25: =SUM(L5:L24) -> 0 | M25: =SUM(M5:M24) -> 0 | ... P25: =SUM(P5:P24) -> 0
A28: 0 | B28: …………………………….. | H28: ………………..…………
A29: 0 | B29: Prepared By: | H29: Checked By:
A30: 0 | H30: (With rubber stamp)
A31: 0 | B31: Contractor Name: | D31: =D1 -> S A M Perera | N31: Invoice No : | Q31: =Q1 -> SAM/CENTRAL/KY/NC/26/DEC/1-A
A32: 0
A33: 0 | B33: PSTN - (RTOM)
A34: 0 | B34: No | C34: TP Number | D34: RTOM | E34: Complete Date | F34: DW-DW | G34: IW-N | H34: DW-CH | I34: DW-LH | J34: DW-RT | K34: DW-DF | L34: ROSSETTE | M34: EARTH ROD | N34: EARTH WIRE | O34: TOP BOLT | P34: CONDUITS | Q34: Pole details & Remarks
A35: 1 | B35: 1
A36: 2 | B36: 2
A37: 3 | B37: 3
A38: 4 | B38: 4
A39: 5 | B39: 5
A40: 6 | B40: 6
A41: 7 | B41: 7
A42: 8 | B42: 8
A43: 9 | B43: 9
A44: 10 | B44: 10
A45: 11 | B45: 11
A46: 12 | B46: 12
... A53: 19 | B53: 19
B54: 20
A55: 0 | B55: Material Totals | F55: =SUM(F35:F54) -> 0 | G55: =SUM(G35:G54) -> 0 | H55: =SUM(H35:H54) -> 0 | I55: =SUM(I35:I54) -> 0 | J55: =SUM(J35:J54) -> 0 | K55: =SUM(K35:K54) -> 0 | L55: =SUM(L35:L54) -> 0 | M55: =SUM(M35:M54) -> 0 | ... P55: =SUM(P35:P54) -> 0
...

Sheet PEO
B1: Contractor Name: | D1: =INVOICE!B1 -> S A M Perera | I1: Invoice No : | L1: =CONCATENATE(INVOICE!H5,"-",INVOICE!H9) -> SAM/CENTRAL/KY/NC/26/DEC/1-A
B3: PEO - (RTOM)
A4: No | B4: No | C4: TP Number | D4: RTOM | E4: Complete Date | F4: CAT 5 | G4: IW-N | H4: DW-DF | I4: DW-ER | J4: DW-EW | K4: ROSSETTE | L4: Remarks
A5: 2 | B5: 1
A6: 3 | B6: 2
A7: 1 | B7: 3
A8: 4 | B8: 4
A9: 5 | B9: 5
A10: 6 | B10: 6
A11: 7 | B11: 7
A12: 8 | B12: 8
A13: 9 | B13: 9
A14: 10 | B14: 10
A15: 11 | B15: 11
A16: 12 | B16: 12
... A24: 20 | B24: 20
A25: 0 | B25: Material Totals | F25: =SUM(F5:F24) -> 0 | G25: =SUM(G5:G24) -> 0 | H25: =SUM(H5:H24) -> 0 | I25: =SUM(I5:I24) -> 0 | J25: =SUM(J5:J24) -> 0 | K25: =SUM(K5:K24) -> 0
A26: 0
A27: 0
A28: 0
A29: 0 | B29: …………………………….. | D29: ………………..…………
A30: 0 | B30: Prepared By: | D30: Checked By:
A31: 0 | D31: (With rubber stamp)
A32: 0 | B32: Contractor Name: | D32: =D1 -> S A M Perera | I32: Invoice No : | L32: =L1 -> SAM/CENTRAL/KY/NC/26/DEC/1-A
A33: 0
A34: 0 | B34: PEO - (RTOM)
A35: 0 | B35: No | C35: TP Number | D35: RTOM | E35: Complete Date | F35: CAT 5 | G35: IW-N | H35: DW-DF | I35: DW-ER | J35: DW-EW | K35: ROSSETTE | L35: Remarks
A36: 1 | B36: 1
A37: 2 | B37: 2
A38: 3 | B38: 3
A39: 4 | B39: 4
A40: 5 | B40: 5
A41: 6 | B41: 6
A42: 7 | B42: 7
A43: 8 | B43: 8
A44: 9 | B44: 9
A45: 10 | B45: 10
A46: 11 | B46: 11
A47: 12 | B47: 12
... A55: 20 | B55: 20
...

Sheet MATERIAL BALANCE SHEET
A1: MATERIAL BALANCE SHEET PEO/NEW CONNECTION
A2: CONTRACTOR NAME - | C2: S A M Perera
A3: INVOICE NUMBER - | C3: SAM/CENTRAL/KY/NC/26/DEC/1
A4: MONTH - | C4: 46357
A5: ITEM | C5: In Hand as at | D5: Issued | E5: Invoiced Usage | F5: Invoiced Wastage | G5: Balance as at
A6: 1 | B6: PROTECTER (NOS)
A7: 2 | B7: C-HOOK (NOS)
A8: 3 | B8: L-HOOK (NOS)
A9: 4 | B9: NUT & BOLT (NOS)
A10: 5 | B10: RETAINERS (NOS)
A11: 6 | B11: DROP WIRE ( M)
A12: 7 | B12: EARTH ROD (NOS)
A13: 8 | B13: INTERNAL WIRE (M)
A14: 9 | B14: EARTH WIRE ( M)
A15: 10 | B15: DROP WIRE CLET (NOS)
A16: 11 | B16: DROP WIRE GRIP (NOS)
A17: 12 | B17: INTERNAL WIRE CLIP (PKT)
... A31: 26 | B31: CABLE TIE
A32: 27
A33: 28
A34: 29
A35: 30
B37: Checked By,
A40: ……………………………………………………………………. | E40: ……..……………………………………
A41: STORES | E41: CONTRACTOR

Sheet INVOICE USAGE
A1: ITEM | C1: Invoiced Usage
A2: 1 | B2: PROTECTER (NOS) | C2: =IFERROR(SUMIF(Calculus!#REF!,'INVOICE USAGE'!B2,Calculus!#REF!)," ")
A3: =SUM(A2+1) -> 2 | B3: C-HOOK (NOS) | C3: =IFERROR(SUMIF(Calculus!#REF!,'INVOICE USAGE'!B3,Calculus!#REF!)," ")
A4: =SUM(A3+1) -> 3 | B4: L-HOOK (NOS) | C4: =IFERROR(SUMIF(Calculus!#REF!,'INVOICE USAGE'!B4,Calculus!#REF!)," ")
A5: =SUM(A4+1) -> 4 | B5: NUT & BOLT (NOS)
A6: =SUM(A5+1) -> 5 | B6: RETAINERS (NOS) | C6: =IFERROR(SUMIF(Calculus!#REF!,'INVOICE USAGE'!B6,Calculus!#REF!)," ")
A7: =SUM(A6+1) -> 6 | B7: DROP WIRE ( M) | C7: =IFERROR(SUMIF(Calculus!#REF!,'INVOICE USAGE'!B7,Calculus!#REF!)," ")
A8: =SUM(A7+1) -> 7 | B8: EARTH ROD (NOS) | C8: =IFERROR(SUMIF(Calculus!#REF!,'INVOICE USAGE'!B8,Calculus!#REF!)," ")
A9: =SUM(A8+1) -> 8 | B9: INTERNAL WIRE (M) | C9: =IFERROR(SUMIF(Calculus!#REF!,'INVOICE USAGE'!B9,Calculus!#REF!)," ")
A10: =SUM(A9+1) -> 9 | B10: EARTH WIRE ( M) | C10: =IFERROR(SUMIF(Calculus!#REF!,'INVOICE USAGE'!B10,Calculus!#REF!)," ")
A11: =SUM(A10+1) -> 10 | B11: DROP WIRE CLET (NOS)
A12: =SUM(A11+1) -> 11 | B12: DROP WIRE GRIP (NOS)
A13: =SUM(A12+1) -> 12 | B13: INTERNAL WIRE CLIP (PKT)
A14: =SUM(A13+1) -> 13 | B14: CONCRETE NAIL (NOS)
A15: 14 | B15: DROP CONNECTOR (NOS)
A16: 15 | B16: CAT 5E CABLE (M) | C16: =IFERROR(SUMIF(Calculus!#REF!,'INVOICE USAGE'!B16,Calculus!#REF!)," ")
A17: 16 | B17: FIBER DROP WIRE | C17: =IFERROR(SUMIF(Calculus!#REF!,'INVOICE USAGE'!B17,Calculus!#REF!)," ")
A18: 17 | B18: SINGLE ROSSET BOX (NOS) | C18: =IFERROR(SUMIF(Calculus!#REF!,'INVOICE USAGE'!B18,Calculus!#REF!)," ")
A19: 18 | B19: RJ45 CONNECTOR
A20: 19 | B20: FIBER ROSET BOX | C20: =IFERROR(SUMIF(Calculus!#REF!,'INVOICE USAGE'!B20,Calculus!#REF!)," ")
A21: 20 | B21: FIBER DROP BOX
A22: 21 | B22: FAC CONNECTOR | C22: =IFERROR(SUMIF(Calculus!#REF!,'INVOICE USAGE'!B22,Calculus!#REF!)," ")
A23: 22 | B23: 12.5X20 TRUNKING | C23: =IFERROR(SUMIF(Calculus!#REF!,'INVOICE USAGE'!B23,Calculus!#REF!)," ")
A24: 23 | B24: SPIRAL CASING 1/4
A25: 24 | B25: PVC CONDUIT (NOS ) 1/2 | C25: =IFERROR(SUMIF(Calculus!#REF!,'INVOICE USAGE'!B25,Calculus!#REF!)," ")
A26: 25 | B26: RJ11 CONNECTOR
A27: 26 | B27: CABLE TIE
A28: 27 | B28: TOP BOLTS | C28: =IFERROR(SUMIF(Calculus!#REF!,'INVOICE USAGE'!B28,Calculus!#REF!)," ")
A29: 28
A30: 29
A31: 30

Sheet Calculus
A2: WORK | B2: CEN | C2: HK | D2: OTHER | E2: OTHER2 | F2: Column2 | G2: Column3
A3: FTTH - DW length- (0-100) | B3: 6750 | C3: 6750 | D3: 6650 | J3: Sn | K3: DW Slabs | L3: New rate
A4: FTTH - DW length- (101-200) | B4: 6750 | C4: 6750 | D4: 7000 | J4: 1 | K4: 0-100 | L4: 6650
A5: FTTH - DW length- (201-300) | B5: 6750 | C5: 6750 | D5: 7800 | J5: 2 | K5: 101-200 | L5: 7000
A6: FTTH - DW length- (301-400) | B6: 6750 | C6: 6750 | D6: 8400 | J6: 3 | K6: 201-300 | L6: 7800
A7: FTTH - DW length- (401-500) | B7: 6750 | C7: 6750 | D7: 8800 | J7: 4 | K7: 301-400 | L7: 8400
A8: FTTH - DW length- (500 ++) | B8: 6750 | C8: 6750 | D8: 9000 | J8: 5 | K8: 401-500 | L8: 8800
A9: FTTH -High Rise Building (Configuration only) | B9: 3800 | C9: 3800 | D9: 3800 | J9: 6 | K9: Above 500 | L9: 9000
A10: FTTH Configuration only | B10: 1000 | C10: 1000 | D10: 1000 | J10: 7 | K10: Highrise Building | L10: 3800
A11: DATA - DW length- (0-100) | B11: 5500 | C11: 5500 | D11: 5000 | J11: 8 | K11: HK/MD | L11: 6750
A12: DATA - DW length- (101-200) | B12: 5500 | C12: 5500 | D12: 5500
A13: DATA - DW length- (201-300) | B13: 5500 | C13: 5500 | D13: 6200
A14: DATA - DW length- (301-400) | B14: 5500 | C14: 5500 | D14: 6800
A15: DATA - DW length- (401-500) | B15: 5500 | C15: 5500 | D15: 7200
A16: DATA - DW length- (500 ++) | B16: 5500 | C16: 5500 | D16: 7400
A17: PSTN- CP/NWP - 1st Con | D17: 2900
A18: PSTN- CP/NWP - 2nd Con | D18: 3000
A19: PSTN- CP/NWP - 3rd Con | D19: 3100
A20: PSTN- CP/NWP - 4th Con | D20: 3200
A21: PSTN - NP/EP - 1st Con | D21: 3000
A22: PSTN - NP/EP - 2nd Con | D22: 3100
A23: PSTN - NP/EP - 3rd Con | D23: 3200
A24: PSTN - NP/EP - 4th Con | D24: 3300
A25: PSTN Con (IDP) | B25: 1500 | C25: 1500 | D25: 1500
A26: IPTV- Single Visit | B26: 1500 | C26: 1500 | D26: 1500
A27: IPTV- Second visit | B27: 1800 | C27: 1800 | D27: 1800
A28: IPTV - 2nd / 3rd Visit (FTTH) | B28: 1500 | C28: 1500 | D28: 1500
A29: 5.6m Pole Installation | B29: 700 | C29: 700 | D29: 700
A30: 5.6m Pole Installation ( Manual) | B30: 900 | C30: 900 | D30: 900
A31: 5.6m Pole Installation & Base Concrete | B31: 4000 | C31: 4000 | D31: 4000
A32: 6.7m Pole Installations | B32: 800 | C32: 800 | D32: 800
A33: 6.7m Pole Installation ( Manual) | B33: 1000 | C33: 1000 | D33: 1000
A34: 6.7m Pole Installation & Base Concrete | B34: 4000 | C34: 4000 | D34: 4000
A35: 8m Pole Installation | B35: 900 | C35: 900 | D35: 900
A36: 8m Pole Installation ( Manual) | B36: 1500 | C36: 1500 | D36: 1500
... A40: 8.0m Poles Installation (External Boom) | B40: 3200 | C40: 3200 | D40: 3200
A43: A | B43: 46023
A44: B | B44: 46054
B45: 46082
B46: 46113
...
