Workbook

Sheet SUMMERY (2)
C3: Kaduwela-Petty cash & Advance status | F3: =NOW() -> 46115.504
C5: Available floats
F7: Rs.
C8: Project advance | F8: 500000
C9: Petty Cash - Kaduwela | F9: 100000
C10: Fuel Advance
C11: CCTV advance | F11: 0
C12: Total | F12: =SUM(F8:F11) -> 600000
C15: Summery details
F16: Amount-Rs.
C17: SLIP - 5642 | D17: Petty Cash / KD / Oct 22 | F17: 0
C18: SLIP - 5336 | D18: Petty Cash / KD / Aug-22 | F18: 0 | G18: Included in Payment Plan - 22.08.2022
C19: Petty cash for the reibursment purpose at welikada Office | F19: =SUM(F18:F18) -> 0 | G19: A
E21: 0
C22: Petty cash for the reibursment purpose at welikada Office
D23: SLIP - 7873 | F23: 988319 | G23: A
C25: Petty bills in hand at Kaduwela office | F25: 141745 | G25: B | J25: =F23+F25+F43+F46+F49+F52+F54 -> #REF!
C29: Project advance - Exp | D29: Fuel Exp / BW / LG 4462 -Boom truck / Nov 23 | E29: OSP-OP-920 | F29: 5000
C30: Project advance - Exp | D30: Fuel Exp / BW / 53-9651 Van / Nov 23 | E30: OSP-OP-920 | F30: 7120
C31: Project advance - Exp | D31: The payment for temporarly hired labours for new connection of RN -R.M.Mumtchas - 2023/11/06-2023/11/11 | E31: OSP-OP-921 | F31: 9000
C32: Project advance - Exp | D32: The payment for temporarly hired labours for new connection of RN -R.M.Mumtchas - 2023/11/01-2023/11/03 | E32: OSP-OP-922 | F32: 4500
C33: Project advance - Exp | D33: The payment for temporarly hired labours for Metro-new connection(Mayura Sandaruwan - 05) - 01.11.2023 to 08.11.2023 | E33: OSP-OP-923 | F33: 12250
C34: Project advance - Exp | D34: Dinner & Refreshement -Softlogic SDWAN fiber link extention work of HK city mail - Nov 23 | E34: OSP-OP-925 | F34: 9620
C35: Project advance - Exp | D35: Ginder rent chgs -Softlogic SDWAN fiber link extention work of HK city mail - Nov 23 | E35: OSP-OP-925 | F35: 3000
C36: Project advance - Exp | D36: Other material chgs -Softlogic SDWAN fiber link extention work of HK city mail - Nov 23 | E36: OSP-OP-925 | F36: 4205
C37: Project advance - Exp | D37: The payment for temporarly hired labours for new connection of BW -R.M.P.Anjula - 2023/11/13-2023/11/19 | E37: OSP-OP-926 | F37: 10500
C38: Project advance - Exp | D38: The payment for temporarly hired labours for new connection of BW -P.V.Asanka - 2023/11/13-2023/11/19 | E38: OSP-OP-927 | F38: 10500
C39: Project advance - Exp | D39: The payment for temporarly hired labours for pole errection work of GQ & NTB - 28.08.2023 to 09.10.2023 (28) | E39: OSP-OP-928 | F39: 12000
C40: Project advance - Exp | D40: Hired labour payment - Coral Saffron HRB project - Dec 23 | E40: OSP-OP-930 | F40: 6000
C41: Project advance - Exp | D41: Hired bracker exp - Coral Saffron HRB project - Dec 23 | E41: OSP-OP-930 | F41: 4000
C43: Project advance for the reibursment purpose at welikada Office | F43: 201 | G43: C | J43: 291580 | L43: Project advance for the reibursment purpose at welikada Office
C46: Project advance Exp at kaduwela Office | F46: =SUM(F45:F45) -> 0 | G46: D
C49: Fuel advance exp at kaduwela Office | F49: =SUM(F48:F48) -> 0 | G49: E
C52: CCTV advance exp at kaduwela Office | F52: =SUM(F51:F51) -> 0 | G52: F
C54: IOUs | F54: =#REF! -> #REF! | G54: G
C56: Cash In Hand | F56: =F58-F54-F49-F43-F25-F23-F46-F52-F22 -> #REF! | G56: H
C58: Total | F58: =F12 -> 600000 | G58: A+B+C+D+E+F+G+H
C62: Nos | D62: Dimensions | F62: Rs
C63: 2 | D63: 5000 | F63: =C63*D63 -> 10000
C64: 5 | D64: 1000 | F64: =C64*D64 -> 5000
...

Sheet IOU-Petty Cash
A1: OSP - IOU | C1: .
A4: Total IOU amount as at | C4: =TODAY() -> 46115 | D4: =SUBTOTAL(9,D6:D1048576) -> 29800 | E4: =200000-(D4+'Summary '!D8) -> 64263.46
A5: Type | B5: IOU # | C5: Name | D5: Amount | E5: IOU Obtain Date | F5: Reson | G5: No of Days
A6: Petty Cash | B6: 10505 | C6: Sahan - MD | D6: 2800 | E6: 45974 | F6: Night work meal charges for NC team (4 prsn ) work at Mobitel eng building (Dinner & evening tea) | G6: =$C$4-E6 -> 141
A7: Petty Cash | B7: 10530 | C7: Chamara - KD | D7: 0 | E7: 45990 | F7: for emergency flood situations | G7: =$C$4-E7 -> 125
A8: Petty Cash | B8: 10533 | C8: Upul - KD | D8: 2000 | E8: 45994 | F8: Purchasing tool for NC work | G8: =$C$4-E8 -> 121
A9: Petty Cash | B9: 11212 | C9: Shantha -NC | D9: 0 | E9: 46085 | F9: Crow bar reparing charges | G9: =$C$4-E9 -> 30
A10: Petty Cash | B10: 11213 | C10: Dushan-HO | D10: 0 | E10: 46101 | F10: Purchase mattress for new staff recruitment HO area | G10: =$C$4-E10 -> 14
A11: Petty Cash | B11: 11214 | C11: Dushan-HO | D11: 0 | E11: 46101 | F11: Purchase mattress for new staff recruitment HO area | G11: =$C$4-E11 -> 14
A12: Petty Cash | B12: 11216 | C12: Rathnasiri - Project | D12: 10000 | E12: 46104 | F12: For fuel arrangement for OSP operation | G12: =$C$4-E12 -> 11
A13: Petty Cash | B13: 11217 | C13: Chamara - KD | D13: 10000 | E13: 46104 | F13: Cans for fuel store for hired vehicle | G13: =$C$4-E13 -> 11
A14: Petty Cash | B14: 11218 | C14: Venura - NC | D14: 5000 | E14: 46107 | F14: For fuel arrangement for OSP SA operation | G14: =$C$4-E14 -> 8
A15: Petty Cash | B15: 11219 | C15: Pamalka | D15: 0 | E15: 46108 | F15: For purchase CDs covers for SF invoice preparation | G15: =$C$4-E15 -> 7
G1046021: =$C$4-E1046021 -> 46115

Sheet IOU-Project Adv
A1: OSP - IOU | C1: .
A4: Total IOU amount as at | C4: =TODAY() -> 46115 | D4: =SUBTOTAL(9,D6:D1048576) -> 294650 | E4: =500000-(D4+'Summary '!D9) -> 44360
A5: Type | B5: IOU # | C5: Name | D5: Amount | E5: IOU Obtain Date | F5: Reson | G5: No of Days
A6: Project advance | B6: 12392 | C6: Hansaka/Prabuddha - KY | D6: 1800 | E6: 45847 | F6: Balance payment for clear backlog (pending pole erections) EP area - JF 2nd Step 2st period | G6: =$C$4-E6 -> 268 | H6: OSP-OP-2106 | I6: 1800 B/L is not refund
A7: Project advance | B7: 11791 | C7: Prabuddha - JF | D7: 50 | E7: 45870 | F7: For clear backlog ( pending pole erections)EP erea - Jaffna 1st step (3rd period) | G7: =$C$4-E7 -> 245 | H7: B/L is not refund
A8: Project advance | B8: 10194 | C8: Milan//Prabuddha - AD/JF | D8: 10500 | E8: 45895 | F8: For clear backlog ( pending pole erections)EP erea - Jaffna 2nd step (3rd period) | G8: =$C$4-E8 -> 220 | H8: OSP-OP-2192 | I8: 10500 B/L is not refund
A9: Project advance | B9: 11109 | C9: Janith - Project | D9: 2000 | E9: 46029 | F9: For bus fees & meal charges for technician travelling Trinco to Ampara site. Hand over to splicing machine | G9: =$C$4-E9 -> 86
A10: Project advance | B10: 11119 | C10: Hansaka - KY | D10: 0 | E10: 46041 | F10: Exp for Hardwary materials purchasing charges for the grand hotel Nuwara eliya urgent work | G10: =$C$4-E10 -> 74
A11: Project advance | B11: 11131 | C11: Amila - project | D11: 0 | E11: 46055 | F11: Cash adv for materials for SMW 3 Dismantaling work | G11: =$C$4-E11 -> 60
A12: Project advance | B12: 11133 | C12: W.L.K Perera -project | D12: 0 | E12: 46058 | F12: Materials purchasing charges for CR jobs (for concreat work) | G12: =$C$4-E12 -> 57
A13: Project advance | B13: 11137 | C13: Adithya-NC | D13: 0 | E13: 46063 | F13: SA/SF - Print banners & leaflets for finding staff for operation | G13: =$C$4-E13 -> 52
A14: Project advance | B14: 11138 | C14: Ashvin-Project | D14: 0 | E14: 46064 | F14: Food arrangement for Nawala Parimary cable laying HRB project night work | G14: =$C$4-E14 -> 51
A15: Project advance | B15: 11139 | C15: S.A.S.C.Perera | D15: 0 | E15: 46065 | F15: Kerosene oil & cortcloth for homagama shifting work | G15: =$C$4-E15 -> 50
A16: Project advance | B16: 11140 | C16: Kavinda -NC | D16: 0 | E16: 46065 | F16: Material for NC work - KX area | G16: =$C$4-E16 -> 50
A17: Project advance | B17: 11141 | C17: M.M.Gurusinghe | D17: 0 | E17: 46067 | F17: Accommodation & food arrangement for pending pole erection work -KO area | G17: =$C$4-E17 -> 48
A18: Project advance | B18: 11142 | C18: Dhanushka - Project | D18: 0 | E18: 46067 | F18: Food arrangement for 32 FDP splicing work ( CEN-OIL-830) | G18: =$C$4-E18 -> 48
A19: Project advance | B19: 11143 | C19: Amila - Project | D19: 0 | E19: 46067 | F19: Food arrangement for Mainframe word place cable laying & ODF splicing night work | G19: =$C$4-E19 -> 48
A20: Project advance | B20: 11144 | C20: Jayasundara- Project | D20: 0 | E20: 46067 | F20: Refreshment arrangement & other expences for school wifi project MUT & KNY area | G20: =$C$4-E20 -> 48
... A23: Project advance | B23: 11147 | C23: Upul - Project | D23: 0 | E23: 46069 | F23: Night work food arrangement for material transport Kaduwela to Rathnapura | G23: =$C$4-E23 -> 46
A24: Project advance | B24: 11148 | C24: Kusumsiri -Project | D24: 0 | E24: 46071 | F24: Food & fuel arrangement for urgent project at Senkadagala Finance Buttala | G24: =$C$4-E24 -> 44 | H24: Bill pending
A25: Project advance | B25: 11149 | C25: Thushantha - Project | D25: 0 | E25: 46071 | F25: Accommodation & food arrangement for RN school Wi-Fi project | G25: =$C$4-E25 -> 44 | H25: Balance need to pay 6966
A26: Project advance | B26: 11150 | C26: Hansaka - KY | D26: 0 | E26: 46073 | F26: Pole concrete work in KY & GP area | G26: =$C$4-E26 -> 42
A27: Project advance | B27: 11301 | C27: Lakmal | D27: 13000 | E27: 46073 | F27: Meal arrangement for BW meeting with DGM & M/OPMC | G27: =$C$4-E27 -> 42 | H27: Original Settlement form pending
A28: Project advance | B28: 11302 | C28: Shanel | D28: 0 | E28: 46073 | F28: Meal arrangement for KT direct team work in GL area to reduce inhand line count | G28: =$C$4-E28 -> 42
A29: Project advance | B29: 11303 | C29: Udara/ Janith - Project | D29: 32000 | E29: 46073 | F29: Pole concrete material purchasing charges AP area | G29: =$C$4-E29 -> 42
A30: Project advance | B30: 11304 | C30: Ashvin-Project | D30: 0 | E30: 46076 | F30: Night work food arrangement for central bus satand HRB project | G30: =$C$4-E30 -> 39
A31: Project advance | B31: 11305 | C31: Amila - project | D31: 0 | E31: 46076 | F31: Night work food arrangement for Sea Me We 3 Cable removing MKT Project | G31: =$C$4-E31 -> 39
A32: Project advance | B32: 11306 | C32: Sajith - Stores | D32: 0 | E32: 46077 | F32: SLT material collecting charges (labours & folk lift) | G32: =$C$4-E32 -> 38
A33: Project advance | B33: 11307 | C33: Amila - project | D33: 0 | E33: 46077 | F33: Night work food arrangement for Capital trust holding project Union place | G33: =$C$4-E33 -> 38
A34: Project advance | B34: 11308 | C34: Dhanushka - Project | D34: 0 | E34: 46079 | F34: Meal arrangement for cable laying work (CEN-OIL-830) project - Breakfast & Lunch | G34: =$C$4-E34 -> 36
A35: Project advance | B35: 11309 | C35: Amila - project | D35: 0 | E35: 46079 | F35: Night work food arrangement for softlogic PLC, One Galle Face | G35: =$C$4-E35 -> 36
A36: Project advance | B36: 11310 | C36: Kavindu -NC | D36: 0 | E36: 46080 | F36: Pole concreat material purchasing charges for BIA area | G36: =$C$4-E36 -> 35
A37: Project advance | B37: 11311 | C37: Kanchana | D37: 0 | E37: 0 | F37: Meal arrangement for additional team deployed from AD toKG rtom due to high workload | G37: =$C$4-E37 -> 46115
A38: Project advance | B38: 11312 | C38: Anuranga | D38: 19500 | E38: 46080 | F38: Accommodation & meal charges for direct team members & driver from KD to NG for support SF Operation | G38: =$C$4-E38 -> 35 | H38: Bata form pending
A39: Project advance | B39: 11313 | C39: Pramitha - Project | D39: 0 | E39: 46080 | F39: Meal arrangement for King Kong Pvt Ltd project night work | G39: =$C$4-E39 -> 35
A40: Project advance | B40: 11314 | C40: Amila - project | D40: 0 | E40: 46080 | F40: Meal arrangement for cargils WTC project night work | G40: =$C$4-E40 -> 35
A41: Project advance | B41: 11315 | C41: Amila - project | D41: 0 | E41: 46084 | F41: Meal arrangement for cable laying & roding work Union place capital trast building night work | G41: =$C$4-E41 -> 31
A42: Project advance | B42: 11317 | C42: Ashvin-Project | D42: 0 | E42: 46086 | F42: Refreshment arrangement for project staff Proposed apartment at Rasaweli rd project | G42: =$C$4-E42 -> 29
A43: Project advance | B43: 11318 | C43: Chandana- Project | D43: 0 | E43: 46086 | F43: Purchase hoe tool for Homagama shifting project | G43: =$C$4-E43 -> 29
A44: Project advance | B44: 11319 | C44: Ashvin-Project | D44: 0 | E44: 46088 | F44: Meal arrangement for Homagma shifting project | G44: =$C$4-E44 -> 27
...

Sheet Summary 
B1: Total | J1: Project Adv | L1: Petty Cash
A2: Petty cash KD | B2: 200000 | J2: 3000 | L2: 6060
A3: Project Advance | B3: 500000 | J3: 8400 | L3: 12000
B4: =SUM(B2:B3) -> 700000 | L4: 10000
J5: =SUM(J2:J4) -> 11400 | L5: 12580
L6: 7280
B7: Total | C7: IOU | D7: Bills | E7: Total | F7: Balance in Hand | L7: 5400
A8: Petty cash | B8: 200000 | C8: ='IOU-Petty Cash'!D4 -> 29800 | D8: =L29 -> 105936.54 | E8: =D8+C8 -> 135736.54 | F8: =B8-E8 -> 64263.46 | L8: 450
A9: Project Advance | B9: 500000 | C9: ='IOU-Project Adv'!D4 -> 294650 | D9: =149590+J5 -> 160990 | E9: =D9+C9 -> 455640 | F9: =B9-E9 -> 44360 | L9: 800
L10: 10000
A11: =TODAY() -> 46115 | L11: 10000
A12: Petty cash | E12: Project Advance | L12: 650
A13: 5000 | B13: 9 | C13: =B13*A13 -> 45000 | E13: 5000 | F13: 7 | G13: =F13*E13 -> 35000 | L13: 7720
A14: 2000 | B14: 0 | C14: =B14*A14 -> 0 | E14: 2000 | F14: 0 | G14: =F14*E14 -> 0 | L14: 3200
A15: 1000 | B15: 3 | C15: =B15*A15 -> 3000 | E15: 1000 | F15: 4 | G15: =F15*E15 -> 4000 | L15: 500
A16: 500 | B16: 0 | C16: =B16*A16 -> 0 | E16: 500 | F16: 2 | G16: =F16*E16 -> 1000 | L16: 350
A17: 100 | B17: 62 | C17: =B17*A17 -> 6200 | E17: 100 | F17: 0 | G17: =F17*E17 -> 0 | L17: 1500
A18: 50 | B18: 100 | C18: =B18*A18 -> 5000 | E18: 50 | F18: 0 | G18: =F18*E18 -> 0 | L18: 3000
A19: 20 | B19: 3 | C19: =B19*A19 -> 60 | E19: 20 | F19: 0 | G19: =F19*E19 -> 0 | L19: 2500
A20: 10 | B20: 0 | C20: =B20*A20 -> 0 | E20: 10 | F20: 0 | G20: =F20*E20 -> 0 | L20: 2500
A21: 5 | B21: 0 | C21: =B21*A21 -> 0 | E21: 5 | F21: 0 | G21: =F21*E21 -> 0 | L21: 2500
A22: 2 | B22: 0 | C22: =B22*A22 -> 0 | E22: 2 | F22: 0 | G22: =F22*E22 -> 0 | L22: 1461.84
A23: 1 | B23: 2 | C23: =B23*A23 -> 2 | E23: 1 | F23: 0 | G23: =F23*E23 -> 0 | L23: 339.8
B24: Cash in hand | C24: =SUM(C13:C23) -> 59262 | F24: Cash in hand | G24: =SUM(G13:G23) -> 40000 | L24: 414.9
C25: =F8-C24 -> 5001.46 | G25: =G24-F9 -> -4360 | L25: 300
L26: 70
L27: 560
L28: 3800
L29: =SUM(L2:L28) -> 105936.54

Sheet 03.04.2026
A1: Type | B1: IOU # | C1: Name | D1: Amount | E1: IOU Obtain Date | F1: Reson | G1: No of Days | H1: Remarks
A2: Project advance | B2: 12392 | C2: Hansaka/Prabuddha - KY | D2: 1800 | E2: 45847 | F2: Balance payment for clear backlog (pending pole erections) EP area - JF 2nd Step 2st period | G2: 268 | H2: Refund from salary
A3: Project advance | B3: 11791 | C3: Prabuddha - JF | D3: 50 | E3: 45870 | F3: For clear backlog ( pending pole erections)EP erea - Jaffna 1st step (3rd period) | G3: 245 | H3: Refund from salary
A4: Project advance | B4: 10194 | C4: Milan//Prabuddha - AD/JF | D4: 10500 | E4: 45895 | F4: For clear backlog ( pending pole erections)EP erea - Jaffna 2nd step (3rd period) | G4: 220 | H4: Refund from salary
A5: Project advance | B5: 11109 | C5: Janith - Project | D5: 2000 | E5: 46029 | F5: For bus fees & meal charges for technician travelling Trinco to Ampara site. Hand over to splicing machine | G5: 86 | H5: Informed several time with mail and over the phone
A6: Project advance | B6: 11301 | C6: Lakmal | D6: 13000 | E6: 46073 | F6: Meal arrangement for BW meeting with DGM & M/OPMC | G6: 42 | H6: Original Settlement form pending
A7: Project advance | B7: 11303 | C7: Udara/ Janith - Project | D7: 32000 | E7: 46073 | F7: Pole concrete material purchasing charges AP area | G7: 42 | H7: Informed several time with mail and over the phone
A8: Project advance | B8: 11312 | C8: Anuranga | D8: 19500 | E8: 46080 | F8: Accommodation & meal charges for direct team members & driver from KD to NG for support SF Operation | G8: 35 | H8: Bata form pending
A9: Project advance | B9: 11326 | C9: Ashvin-Project | D9: 10000 | E9: 46095 | F9: To purchase material for SEA-ME-WE-06 building project | G9: 20
A10: Project advance | B10: 11331 | C10: Kusumsiri -Project | D10: 20000 | E10: 46101 | F10: Fuel arrangement for BW vehicle for two days work at Katharagama area | G10: 14 | H10: Original Settlement form pending
A11: Project advance | B11: 11339 | C11: Amila - Project | D11: 11000 | E11: 46108 | F11: To purchase Nylon rope roll for OSP project rodding & Laying work | G11: 7
A12: Project advance | B12: 11340 | C12: Ashvin-Project | D12: 10000 | E12: 46108 | F12: To arrange small scale material for CBS FTTH development project | G12: 7
A13: Project advance | B13: 11341 | C13: Shanel-GL | D13: 100000 | E13: 46109 | F13: For SF contractors in Southern province due to month end SF target achievement | G13: 6
A14: Project advance | B14: 11342 | C14: Keshan-NC | D14: 2800 | E14: 46111 | F14: Night work meal arrangement for KCC Building NC work | G14: 4
A15: Project advance | B15: 11343 | C15: Siriwardhane - Project | D15: 3500 | E15: 46112 | F15: Night work food arrangement for primary cable laying Mtro habitat project | G15: 3
A16: Project advance | B16: 11344 | C16: Dhanushka - Project | D16: 3500 | E16: 46112 | F16: Night work food arrangement for Nawam mawatha project | G16: 3
A17: Project advance | B17: 11345 | C17: Ravindu- NC | D17: 50000 | E17: 46113 | F17: GR plasa trincomalee | G17: 2
A18: Project advance | B18: 11346 | C18: Amila - Project | D18: 1000 | E18: 46114 | F18: Meal arrangement for splicing work in Capital trust union place night work | G18: 1
A19: Project advance | B19: 11347 | C19: Amila -Project | D19: 2000 | E19: 46115 | F19: To purchase material for pole concrete MKT projects | G19: 0
A20: Project advance | B20: 11348 | C20: Ashvin-Project | D20: 30000 | E20: 46115 | F20: To arrange small scale material for CBS FTTH development project | G20: 0
C21: Total IOU | D21: =SUM(D2:D20) -> 322650
D22: Rs.
A23: OCA | D23: 500000
A24: Payments for reimbursement | C24: =149590 -> 149590
A25: IOU | C25: =D21 -> 322650
A26: Settlement error return | C26: =8400+3000+2000 -> 13400
A27: Total cash allocation | D27: =SUM(C24:C26) -> 485640
A28: Balance Inhand as at 03.04.2026 | D28: =D23-D27 -> 14360

Sheet Summary 01
C3: Kaduwela-Petty cash & Advance status | F3: =NOW() -> 46115.504
C5: Available floats
F7: Rs.
C8: Project advance | F8: 500000
C9: Spacial project advance | F9: =400000+200000 -> 600000
C10: Petty Cash - Kaduwela | F10: 200000
F12: 0
C13: Total | F13: =SUM(F8:F12) -> 1300000
C16: Summery details
F17: Amount-Rs.
C18: SLIP - 5642 | D18: Petty Cash / KD / Oct 22 | F18: 0
C19: SLIP - 5336 | D19: Petty Cash / KD / Aug-22 | F19: 0 | G19: Included in Payment Plan - 22.08.2022
C20: Petty cash for the reibursment purpose at welikada Office | F20: =SUM(F19:F19) -> 0 | G20: A
E22: 0
C23: Petty cash for the reibursment purpose at welikada Office
D24: SLIP - | F24: 0 | G24: A
C26: Petty bills in hand at Kaduwela office | G26: B
C28: Cash advance memo in hand | D28: OSP - OP - 1537 | F28: 15000 | G28: C
C30: Peoject advance reibursment purpose at welikkada office
C32: Special project advance (Set 01/ 02/ 03/ 04/ ) | F32: 413409 | G32: D
C34: Type | D34: Description | E34: Amount (Rs.) | F34: Total | G34: Column6 | H34: Column8 | I34: Column9 | J34: paid | K34: Column11
C49: Project advance amount
C50: Balance to be paid
C51: Total project advance | E51: =E49-E50 -> 0 | F51: E
C58: IOUs | F58: 426945 | G58: F
C60: Cash In Hand | G60: G
C62: Total | G62: A+B+C+D+E+F+G
C66: Dimensions | D66: Non | E66: Rs
C67: 5000
C68: 1000
C69: 500
C70: 100
C71: 50
C72: 20
C73: Coins
F74: =E73+E72+E71+E70+E69+E67+E68 -> 0

Sheet Sheet6
A1: 15000 | B1: 15230 | C1: =A1-B1 -> -230
A2: 25000 | B2: 24680 | C2: =A2-B2 -> 320
A3: 25000 | B3: 24640 | C3: =A3-B3 -> 360
C4: =SUM(C1:C3) -> 450

Sheet Sheet5
D1: Amount-Rs.
A2: Project advance - Exp | B2: The payment for temporarly hired labours for Metro-new connection - 13.07.2023 to 17.07.2023 | C2: OSP-OP-677 | D2: 8500
A3: Project advance - Exp | B3: The food expenses for other regional teams for participating Ftth campaing of Matara - Jul 23 | C3: OSP-OP-678 | D3: 53010
A4: Project advance - Exp | B4: The payment for temporarly hired labours for new connection of GQ - 10.07.2023 to 16.07.2023 | C4: OSP-OP-680 | D4: 29250
A5: Project advance - Exp | B5: The payment for temporarly hired labours for Metro-new connection - 24.06.2023 to 29.06.2023 | C5: OSP-OP-681 | D5: 3400
A6: Project advance - Exp | B6: The payment for temporarly hired labours for Metro-new connection - 24.06.2023 to 29.06.2023 | C6: OSP-OP-684 | D6: 3400
A7: Project advance - Exp | B7: Meal arrangment chgs for direct team - Cargills SQ HRB project of Bandarawela - Jul 23 | C7: OSP-OP-685 | D7: 22325
A8: Project advance - Exp | B8: Accomodation chgs for direct team - Cargills SQ HRB project of Bandarawela - Jul 23 | C8: OSP-OP-685 | D8: 6700
A9: Project advance - Exp | B9: Other material exp - Cargills SQ HRB project of Bandarawela - Jul 23 | C9: OSP-OP-685 | D9: 7850
A10: Project advance - Exp | B10: The food expenses for other regional teams for participating Ftth campaing of Matara - Jul 23 | C10: OSP-OP-686 | D10: 33940
A11: Project advance - Exp | B11: The payment for temporarly hired labours for new connection of GQ - 08.05.2023 to 06.06.2023 | C11: OSP-OP-688 | D11: 12000
A12: Project advance - Exp | B12: The payment for temporarly hired labours for new connection of GQ - 06.06.2023 to 17.06.2023 | C12: OSP-OP-689 | D12: 12000
A13: Project advance - Exp | B13: The payment for temporarly hired labours for new connection of GQ - 17.06.2023 to 27.06.2023 | C13: OSP-OP-690 | D13: 12000
A14: Project advance - Exp | B14: The payment for Step ladders purchasing - for the newconnection of Bandaragama - Jul 23 | C14: OSP-OP-691 | D14: 60750
D16: =SUM(D2:D15) -> 265125
D19: 265125

Sheet Sheet4
E1: Rs.
B2: Petty Cash - Kaduwela | C2: Reibursement procees | E2: 100000
B3: OSP Project advance | C3: Reibursement procees | E3: 500000
B4: OSP Fuel Advance | C4: Settlement | E4: 450000
B5: Total Amount | E5: =SUM(E2:E4) -> 1050000
B9: Status as at 26.06.2023 | C9: Rs.
B10: Kaduwela petty cash for the reibursment purpose at welikada Office | C10: ='SUMMERY (2)'!F23 -> 988319
B11: Petty bills in hand at Kaduwela office | C11: ='SUMMERY (2)'!F25 -> 141745
B12: Project advance for the reibursment purpose at welikada Office | C12: ='SUMMERY (2)'!F43 -> 201
B13: Fuel advance exp need to be settled | C13: ='SUMMERY (2)'!F49 -> 0
B14: Total IOUs | C14: ='SUMMERY (2)'!F54 -> #REF!
B15: Cash In Hand | C15: ='SUMMERY (2)'!F56 -> #REF!
B16: Total | C16: =SUM(C10:C15) -> #REF!

Sheet Sheet3

Sheet Sheet2
B2: IOU # | C2: Name | D2: Amounts | E2: IOU Obtain Date | F2: Reson | J2: No of Days as at 16.08.2022
B3: 618 | C3: Venura | D3: 50000 | E3: 44758 | F3: Deisel purchasing - Company double cab | J3: 31
B4: 619 | C4: Hansaka + Mishara | D4: 96600 | E4: 44758 | F4: Deisel purchasing - OSP vehicle Kandy | J4: 31
B5: 620 | C5: Madawa + Chamara | D5: 107200 | E5: 44758 | F5: Deisel purchasing - OSP vehicle Kaduwela | J5: 31
B6: 622 | C6: Chamara | D6: 38000 | E6: 44760 | F6: Deisel purchasing - OSP vehicle Kaduwela | J6: 29
D7: =SUM(D3:D6) -> 291800
C8: Cash in hand | D8: =D9-D7 -> 108200
D9: 400000

Sheet Sheet1
A2: 44525 | B2: 582.5
B3: 350
B4: 661.3
B5: 1985
B6: 155
B7: 308
B8: 440
B9: 2787
B10: 220
B11: 1132
B12: 2263
B13: 1361
B14: 530
... B33: 734
B34: =SUM(B2:B33) -> 29685
